Workbook

Sheet Dashboard
A1: Clenny & Clanny Shipment Tracker
A3: Selected Shipment ID | B3: =Settlement!B2 -> SHP-002 | D3: Partner | E3: Contribution % | F3: Projected Payout
A4: Product | B4: {=IF($B$3="","",XLOOKUP($B$3,'Shipment Setup'!$A:$A,'Shipment Setup'!$B:$B,""))} -> Copenhagen | D4: Clenny | E4: =Settlement!B14 -> 0.063798412 | F4: =Settlement!B24 -> 826.82742
A5: Status | B5: {=IF($B$3="","",XLOOKUP($B$3,'Shipment Setup'!$A:$A,'Shipment Setup'!$C:$C,""))} -> In Transit | D5: Clanny | E5: =Settlement!B15 -> 0.93620159 | F5: =Settlement!B25 -> 12133.173
A6: Boxes Coming | B6: {=IF($B$3="","",XLOOKUP($B$3,'Shipment Setup'!$A:$A,'Shipment Setup'!$D:$D,""))} -> 2 | D6: Total | E6: =SUM(E4:E5) -> 1 | F6: =SUM(F4:F5) -> 12960
A7: Total Cases | B7: {=IF($B$3="","",XLOOKUP($B$3,'Shipment Setup'!$A:$A,'Shipment Setup'!$J:$J,""))} -> 12
A8: Total Rolls | B8: {=IF($B$3="","",XLOOKUP($B$3,'Shipment Setup'!$A:$A,'Shipment Setup'!$K:$K,""))} -> 216 | D8: Metric | E8: Value | F8: Notes
A9: Total Cans | B9: {=IF($B$3="","",XLOOKUP($B$3,'Shipment Setup'!$A:$A,'Shipment Setup'!$L:$L,""))} -> 1080 | D9: Product cost | E9: {=IF($B$3="","",XLOOKUP($B$3,'Shipment Setup'!$A:$A,'Shipment Setup'!$N:$N,""))} -> 7296 | F9: Two boxes × 6 cases × $608/case
A10: Cost per Case | B10: {=IF($B$3="","",XLOOKUP($B$3,'Shipment Setup'!$A:$A,'Shipment Setup'!$M:$M,""))} -> 608 | D10: Projected revenue | E10: {=IF($B$3="","",XLOOKUP($B$3,'Shipment Setup'!$A:$A,'Shipment Setup'!$P:$P,""))} -> 12960 | F10: Total cans × target sale price
A11: Product Cost | B11: {=IF($B$3="","",XLOOKUP($B$3,'Shipment Setup'!$A:$A,'Shipment Setup'!$N:$N,""))} -> 7296 | D11: Projected profit | E11: =Settlement!B19 -> 5107.14 | F11: Revenue minus product and approved ops
A12: Target Sale Price/Can | B12: {=IF($B$3="","",XLOOKUP($B$3,'Shipment Setup'!$A:$A,'Shipment Setup'!$O:$O,""))} -> 12 | D12: Ops entered | E12: =Settlement!B9 -> 556.86 | F12: Currently zero unless added in Operations Ledger
A13: Projected Revenue | B13: {=IF($B$3="","",XLOOKUP($B$3,'Shipment Setup'!$A:$A,'Shipment Setup'!$P:$P,""))} -> 12960 | D13: Sales entered | E13: =Settlement!B17 -> 0 | F13: Pulled from Sales Ledger
A14: Projected Profit After Ops | B14: =Settlement!B19 -> 5107.14 | D14: Inventory remaining | E14: =Settlement!B30 -> 1080 | F14: Cans not yet sold
D15: Check | E15: =Settlement!B36 -> 0 | F15: Should be $0.00 when formulas balance
A16: Clenny Product Invest | B16: {=IF($B$3="","",XLOOKUP($B$3,'Shipment Setup'!$A:$A,'Shipment Setup'!$Q:$Q,""))} -> 501
A17: Clanny Product Invest | B17: {=IF($B$3="","",XLOOKUP($B$3,'Shipment Setup'!$A:$A,'Shipment Setup'!$R:$R,""))} -> 6795
A18: Clenny Approved Ops | B18: =Settlement!B7 -> 0
A19: Clanny Approved Ops | B19: =Settlement!B8 -> 556.86
A20: Clenny Contribution % | B20: =Settlement!B14 -> 0.063798412
A21: Clanny Contribution % | B21: =Settlement!B15 -> 0.93620159
A23: Clenny Projected Payout | B23: =Settlement!B24 -> 826.82742
A24: Clanny Projected Payout | B24: =Settlement!B25 -> 12133.173
A25: Inventory Remaining, Cans | B25: =Settlement!B30 -> 1080

Sheet Shipment Setup
A1: Shipment ID | B1: Product | C1: Status | D1: Boxes Ordered | E1: Cases/Box | F1: Rolls/Case | G1: Cans/Roll | H1: Cans/Case | I1: Cans/Box | J1: Cases Ordered | K1: Rolls Ordered | L1: Total Cans | M1: Cost/Case | N1: Total Product Cost | O1: Target Sale Price/Can | P1: Projected Revenue | Q1: Clenny Product Invest | R1: Clanny Product Invest | S1: Notes
A2: SHP-002 | B2: Copenhagen | C2: In Transit | D2: 2 | E2: 6 | F2: 18 | G2: 5 | H2: =F2*G2 -> 90 | I2: =E2*H2 -> 540 | J2: =D2*E2 -> 12 | K2: =J2*F2 -> 216 | L2: =D2*I2 -> 1080 | M2: 608 | N2: =J2*M2 -> 7296 | O2: 12 | P2: =L2*O2 -> 12960 | Q2: 501 | R2: =N2-Q2 -> 6795 | S2: Expected arrival: July 1. Base planning assumption: most cans sell at $12 each, with some possibly sold at $13.
A3: SHP-003 | B3: Grizzly | C3: Planned | H3: =IF(A3="","",F3*G3) -> 0 | I3: =IF(A3="","",E3*H3) -> 0 | J3: =IF(A3="","",D3*E3) -> 0 | K3: =IF(A3="","",J3*F3) -> 0 | L3: =IF(A3="","",D3*I3) -> 0 | M3: 497 | N3: =IF(A3="","",J3*M3) -> 0 | P3: =IF(A3="","",L3*O3) -> 0 | R3: =IF(A3="","",N3-Q3) -> 0 | S3: Per Clanny 7/1: Grizzly letter F, $497/case. PO guy MAJ charges $250/box starting this shipment, plus one case for himself. Boxes/case config TBD.
H4: =IF(A4="","",F4*G4) | I4: =IF(A4="","",E4*H4) | J4: =IF(A4="","",D4*E4) | K4: =IF(A4="","",J4*F4) | L4: =IF(A4="","",D4*I4) | N4: =IF(A4="","",J4*M4) | P4: =IF(A4="","",L4*O4) | R4: =IF(A4="","",N4-Q4)
H5: =IF(A5="","",F5*G5) | I5: =IF(A5="","",E5*H5) | J5: =IF(A5="","",D5*E5) | K5: =IF(A5="","",J5*F5) | L5: =IF(A5="","",D5*I5) | N5: =IF(A5="","",J5*M5) | P5: =IF(A5="","",L5*O5) | R5: =IF(A5="","",N5-Q5)
H6: =IF(A6="","",F6*G6) | I6: =IF(A6="","",E6*H6) | J6: =IF(A6="","",D6*E6) | K6: =IF(A6="","",J6*F6) | L6: =IF(A6="","",D6*I6) | N6: =IF(A6="","",J6*M6) | P6: =IF(A6="","",L6*O6) | R6: =IF(A6="","",N6-Q6)
H7: =IF(A7="","",F7*G7) | I7: =IF(A7="","",E7*H7) | J7: =IF(A7="","",D7*E7) | K7: =IF(A7="","",J7*F7) | L7: =IF(A7="","",D7*I7) | N7: =IF(A7="","",J7*M7) | P7: =IF(A7="","",L7*O7) | R7: =IF(A7="","",N7-Q7)
H8: =IF(A8="","",F8*G8) | I8: =IF(A8="","",E8*H8) | J8: =IF(A8="","",D8*E8) | K8: =IF(A8="","",J8*F8) | L8: =IF(A8="","",D8*I8) | N8: =IF(A8="","",J8*M8) | P8: =IF(A8="","",L8*O8) | R8: =IF(A8="","",N8-Q8)
H9: =IF(A9="","",F9*G9) | I9: =IF(A9="","",E9*H9) | J9: =IF(A9="","",D9*E9) | K9: =IF(A9="","",J9*F9) | L9: =IF(A9="","",D9*I9) | N9: =IF(A9="","",J9*M9) | P9: =IF(A9="","",L9*O9) | R9: =IF(A9="","",N9-Q9)
H10: =IF(A10="","",F10*G10) | I10: =IF(A10="","",E10*H10) | J10: =IF(A10="","",D10*E10) | K10: =IF(A10="","",J10*F10) | L10: =IF(A10="","",D10*I10) | N10: =IF(A10="","",J10*M10) | P10: =IF(A10="","",L10*O10) | R10: =IF(A10="","",N10-Q10)
H11: =IF(A11="","",F11*G11) | I11: =IF(A11="","",E11*H11) | J11: =IF(A11="","",D11*E11) | K11: =IF(A11="","",J11*F11) | L11: =IF(A11="","",D11*I11) | N11: =IF(A11="","",J11*M11) | P11: =IF(A11="","",L11*O11) | R11: =IF(A11="","",N11-Q11)
H12: =IF(A12="","",F12*G12) | I12: =IF(A12="","",E12*H12) | J12: =IF(A12="","",D12*E12) | K12: =IF(A12="","",J12*F12) | L12: =IF(A12="","",D12*I12) | N12: =IF(A12="","",J12*M12) | P12: =IF(A12="","",L12*O12) | R12: =IF(A12="","",N12-Q12)
H13: =IF(A13="","",F13*G13) | I13: =IF(A13="","",E13*H13) | J13: =IF(A13="","",D13*E13) | K13: =IF(A13="","",J13*F13) | L13: =IF(A13="","",D13*I13) | N13: =IF(A13="","",J13*M13) | P13: =IF(A13="","",L13*O13) | R13: =IF(A13="","",N13-Q13)
H14: =IF(A14="","",F14*G14) | I14: =IF(A14="","",E14*H14) | J14: =IF(A14="","",D14*E14) | K14: =IF(A14="","",J14*F14) | L14: =IF(A14="","",D14*I14) | N14: =IF(A14="","",J14*M14) | P14: =IF(A14="","",L14*O14) | R14: =IF(A14="","",N14-Q14)
H15: =IF(A15="","",F15*G15) | I15: =IF(A15="","",E15*H15) | J15: =IF(A15="","",D15*E15) | K15: =IF(A15="","",J15*F15) | L15: =IF(A15="","",D15*I15) | N15: =IF(A15="","",J15*M15) | P15: =IF(A15="","",L15*O15) | R15: =IF(A15="","",N15-Q15)
... H51: =IF(A51="","",F51*G51) | I51: =IF(A51="","",E51*H51) | J51: =IF(A51="","",D51*E51) | K51: =IF(A51="","",J51*F51) | L51: =IF(A51="","",D51*I51) | N51: =IF(A51="","",J51*M51) | P51: =IF(A51="","",L51*O51) | R51: =IF(A51="","",N51-Q51)

Sheet Operations Ledger
A1: Shipment ID | B1: Owner | C1: Date | D1: Category | E1: Amount | F1: Included in Settlement? | G1: Description / Notes | H1: Receipt / Proof Link
A2: SHP-002 | B2: Clanny | C2: =DATE(2026,7,1) -> 46204 | D2: Vehicle Rental | E2: 118.32 | F2: Yes | G2: Rental per Clanny 7/1 report
A3: SHP-002 | B3: Clanny | C3: =DATE(2026,7,1) -> 46204 | D3: Gas | E3: 100 | F3: Yes | G3: Actual (confirmed, was initially an estimate)
A4: SHP-002 | B4: Clanny | C4: =DATE(2026,7,1) -> 46204 | D4: Cargo | E4: 52 | F4: Yes | G4: Cargo fee
A5: SHP-002 | B5: Clanny | C5: =DATE(2026,7,1) -> 46204 | D5: Cargo Labor | E5: 50 | F5: Yes | G5: Cargo person
A6: SHP-002 | B6: Clanny | C6: =DATE(2026,7,1) -> 46204 | D6: Mailing PO HNL-MAJ | E6: =118.27*2 -> 236.54 | F6: Yes | G6: $118.27 per box × 2 boxes
A7: SHP-002 | B7: Clanny | C7: =DATE(2026,7,1) -> 46204 | D7: Mail Person Fee | E7: 200 | F7: No | G7: Payable AFTER product sold — not paid yet. Change Included to Yes once paid.
A8: SHP-002 | C8: =DATE(2026,7,1) -> 46204 | F8: Yes
A9: SHP-002 | C9: =DATE(2026,7,1) -> 46204 | F9: Yes
A10: SHP-002 | C10: =DATE(2026,7,1) -> 46204 | F10: Yes
A11: SHP-002 | C11: =DATE(2026,7,1) -> 46204 | F11: Yes
A12: SHP-002 | C12: =DATE(2026,7,1) -> 46204 | F12: Yes
A13: SHP-002 | C13: =DATE(2026,7,1) -> 46204 | F13: Yes
A14: SHP-002 | C14: =DATE(2026,7,1) -> 46204 | F14: Yes
A15: SHP-002 | C15: =DATE(2026,7,1) -> 46204 | F15: Yes
A16: SHP-002 | C16: =DATE(2026,7,1) -> 46204 | F16: Yes
A17: SHP-002 | C17: =DATE(2026,7,1) -> 46204 | F17: Yes
A18: SHP-002 | C18: =DATE(2026,7,1) -> 46204 | F18: Yes
A19: SHP-002 | C19: =DATE(2026,7,1) -> 46204 | F19: Yes
... A51: SHP-002 | C51: =DATE(2026,7,1) -> 46204 | F51: Yes

Sheet Sales Ledger
A1: Shipment ID | B1: Date | C1: Product | D1: Customer / Store | E1: Boxes Sold | F1: Cases Sold | G1: Rolls Sold | H1: Loose Cans Sold | I1: Total Cans Sold | J1: Price/Can | K1: Gross Sales | L1: Collected By | M1: Payment Status | N1: Notes
A2: SHP-002 | C2: =IF($A2="","",VLOOKUP($A2,'Shipment Setup'!$A:$S,2,FALSE)) -> Copenhagen | I2: =IF($A2="","",E2*VLOOKUP($A2,'Shipment Setup'!$A:$S,9,FALSE)+F2*VLOOKUP($A2,'Shipment Setup'!$A:$S,8,FALSE)+G2*VLOOKUP($A2,'Shipment Setup'!$A:$S,7,FALSE)+H2) -> 0 | J2: {=IF(A2="","",IFERROR(XLOOKUP(A2,'Shipment Setup'!$A:$A,'Shipment Setup'!$O:$O,""),""))} -> 12 | K2: =IF($A2="","",$I2*$J2) -> 0
A3: SHP-002 | C3: =IF($A3="","",VLOOKUP($A3,'Shipment Setup'!$A:$S,2,FALSE)) -> Copenhagen | I3: =IF($A3="","",E3*VLOOKUP($A3,'Shipment Setup'!$A:$S,9,FALSE)+F3*VLOOKUP($A3,'Shipment Setup'!$A:$S,8,FALSE)+G3*VLOOKUP($A3,'Shipment Setup'!$A:$S,7,FALSE)+H3) -> 0 | J3: {=IF(A3="","",IFERROR(XLOOKUP(A3,'Shipment Setup'!$A:$A,'Shipment Setup'!$O:$O,""),""))} -> 12 | K3: =IF($A3="","",$I3*$J3) -> 0
A4: SHP-002 | C4: =IF($A4="","",VLOOKUP($A4,'Shipment Setup'!$A:$S,2,FALSE)) -> Copenhagen | I4: =IF($A4="","",E4*VLOOKUP($A4,'Shipment Setup'!$A:$S,9,FALSE)+F4*VLOOKUP($A4,'Shipment Setup'!$A:$S,8,FALSE)+G4*VLOOKUP($A4,'Shipment Setup'!$A:$S,7,FALSE)+H4) -> 0 | J4: {=IF(A4="","",IFERROR(XLOOKUP(A4,'Shipment Setup'!$A:$A,'Shipment Setup'!$O:$O,""),""))} -> 12 | K4: =IF($A4="","",$I4*$J4) -> 0 | M4: Paid
A5: SHP-002 | C5: =IF($A5="","",VLOOKUP($A5,'Shipment Setup'!$A:$S,2,FALSE)) -> Copenhagen | I5: =IF($A5="","",E5*VLOOKUP($A5,'Shipment Setup'!$A:$S,9,FALSE)+F5*VLOOKUP($A5,'Shipment Setup'!$A:$S,8,FALSE)+G5*VLOOKUP($A5,'Shipment Setup'!$A:$S,7,FALSE)+H5) -> 0 | J5: {=IF(A5="","",IFERROR(XLOOKUP(A5,'Shipment Setup'!$A:$A,'Shipment Setup'!$O:$O,""),""))} -> 12 | K5: =IF($A5="","",$I5*$J5) -> 0 | M5: Paid
A6: SHP-002 | C6: =IF($A6="","",VLOOKUP($A6,'Shipment Setup'!$A:$S,2,FALSE)) -> Copenhagen | I6: =IF($A6="","",E6*VLOOKUP($A6,'Shipment Setup'!$A:$S,9,FALSE)+F6*VLOOKUP($A6,'Shipment Setup'!$A:$S,8,FALSE)+G6*VLOOKUP($A6,'Shipment Setup'!$A:$S,7,FALSE)+H6) -> 0 | J6: {=IF(A6="","",IFERROR(XLOOKUP(A6,'Shipment Setup'!$A:$A,'Shipment Setup'!$O:$O,""),""))} -> 12 | K6: =IF($A6="","",$I6*$J6) -> 0 | M6: Paid
A7: SHP-002 | C7: =IF($A7="","",VLOOKUP($A7,'Shipment Setup'!$A:$S,2,FALSE)) -> Copenhagen | I7: =IF($A7="","",E7*VLOOKUP($A7,'Shipment Setup'!$A:$S,9,FALSE)+F7*VLOOKUP($A7,'Shipment Setup'!$A:$S,8,FALSE)+G7*VLOOKUP($A7,'Shipment Setup'!$A:$S,7,FALSE)+H7) -> 0 | J7: {=IF(A7="","",IFERROR(XLOOKUP(A7,'Shipment Setup'!$A:$A,'Shipment Setup'!$O:$O,""),""))} -> 12 | K7: =IF($A7="","",$I7*$J7) -> 0 | M7: Paid
A8: SHP-002 | C8: =IF($A8="","",VLOOKUP($A8,'Shipment Setup'!$A:$S,2,FALSE)) -> Copenhagen | I8: =IF($A8="","",E8*VLOOKUP($A8,'Shipment Setup'!$A:$S,9,FALSE)+F8*VLOOKUP($A8,'Shipment Setup'!$A:$S,8,FALSE)+G8*VLOOKUP($A8,'Shipment Setup'!$A:$S,7,FALSE)+H8) -> 0 | J8: {=IF(A8="","",IFERROR(XLOOKUP(A8,'Shipment Setup'!$A:$A,'Shipment Setup'!$O:$O,""),""))} -> 12 | K8: =IF($A8="","",$I8*$J8) -> 0 | M8: Paid
A9: SHP-002 | C9: =IF($A9="","",VLOOKUP($A9,'Shipment Setup'!$A:$S,2,FALSE)) -> Copenhagen | I9: =IF($A9="","",E9*VLOOKUP($A9,'Shipment Setup'!$A:$S,9,FALSE)+F9*VLOOKUP($A9,'Shipment Setup'!$A:$S,8,FALSE)+G9*VLOOKUP($A9,'Shipment Setup'!$A:$S,7,FALSE)+H9) -> 0 | J9: {=IF(A9="","",IFERROR(XLOOKUP(A9,'Shipment Setup'!$A:$A,'Shipment Setup'!$O:$O,""),""))} -> 12 | K9: =IF($A9="","",$I9*$J9) -> 0 | M9: Paid
A10: SHP-002 | C10: =IF($A10="","",VLOOKUP($A10,'Shipment Setup'!$A:$S,2,FALSE)) -> Copenhagen | I10: =IF($A10="","",E10*VLOOKUP($A10,'Shipment Setup'!$A:$S,9,FALSE)+F10*VLOOKUP($A10,'Shipment Setup'!$A:$S,8,FALSE)+G10*VLOOKUP($A10,'Shipment Setup'!$A:$S,7,FALSE)+H10) -> 0 | J10: {=IF(A10="","",IFERROR(XLOOKUP(A10,'Shipment Setup'!$A:$A,'Shipment Setup'!$O:$O,""),""))} -> 12 | K10: =IF($A10="","",$I10*$J10) -> 0 | M10: Paid
A11: SHP-002 | C11: =IF($A11="","",VLOOKUP($A11,'Shipment Setup'!$A:$S,2,FALSE)) -> Copenhagen | I11: =IF($A11="","",E11*VLOOKUP($A11,'Shipment Setup'!$A:$S,9,FALSE)+F11*VLOOKUP($A11,'Shipment Setup'!$A:$S,8,FALSE)+G11*VLOOKUP($A11,'Shipment Setup'!$A:$S,7,FALSE)+H11) -> 0 | J11: {=IF(A11="","",IFERROR(XLOOKUP(A11,'Shipment Setup'!$A:$A,'Shipment Setup'!$O:$O,""),""))} -> 12 | K11: =IF($A11="","",$I11*$J11) -> 0 | M11: Paid
A12: SHP-002 | C12: =IF($A12="","",VLOOKUP($A12,'Shipment Setup'!$A:$S,2,FALSE)) -> Copenhagen | I12: =IF($A12="","",E12*VLOOKUP($A12,'Shipment Setup'!$A:$S,9,FALSE)+F12*VLOOKUP($A12,'Shipment Setup'!$A:$S,8,FALSE)+G12*VLOOKUP($A12,'Shipment Setup'!$A:$S,7,FALSE)+H12) -> 0 | J12: {=IF(A12="","",IFERROR(XLOOKUP(A12,'Shipment Setup'!$A:$A,'Shipment Setup'!$O:$O,""),""))} -> 12 | K12: =IF($A12="","",$I12*$J12) -> 0 | M12: Paid
A13: SHP-002 | C13: =IF($A13="","",VLOOKUP($A13,'Shipment Setup'!$A:$S,2,FALSE)) -> Copenhagen | I13: =IF($A13="","",E13*VLOOKUP($A13,'Shipment Setup'!$A:$S,9,FALSE)+F13*VLOOKUP($A13,'Shipment Setup'!$A:$S,8,FALSE)+G13*VLOOKUP($A13,'Shipment Setup'!$A:$S,7,FALSE)+H13) -> 0 | J13: {=IF(A13="","",IFERROR(XLOOKUP(A13,'Shipment Setup'!$A:$A,'Shipment Setup'!$O:$O,""),""))} -> 12 | K13: =IF($A13="","",$I13*$J13) -> 0 | M13: Paid
A14: SHP-002 | C14: =IF($A14="","",VLOOKUP($A14,'Shipment Setup'!$A:$S,2,FALSE)) -> Copenhagen | I14: =IF($A14="","",E14*VLOOKUP($A14,'Shipment Setup'!$A:$S,9,FALSE)+F14*VLOOKUP($A14,'Shipment Setup'!$A:$S,8,FALSE)+G14*VLOOKUP($A14,'Shipment Setup'!$A:$S,7,FALSE)+H14) -> 0 | J14: {=IF(A14="","",IFERROR(XLOOKUP(A14,'Shipment Setup'!$A:$A,'Shipment Setup'!$O:$O,""),""))} -> 12 | K14: =IF($A14="","",$I14*$J14) -> 0 | M14: Paid
A15: SHP-002 | C15: =IF($A15="","",VLOOKUP($A15,'Shipment Setup'!$A:$S,2,FALSE)) -> Copenhagen | I15: =IF($A15="","",E15*VLOOKUP($A15,'Shipment Setup'!$A:$S,9,FALSE)+F15*VLOOKUP($A15,'Shipment Setup'!$A:$S,8,FALSE)+G15*VLOOKUP($A15,'Shipment Setup'!$A:$S,7,FALSE)+H15) -> 0 | J15: {=IF(A15="","",IFERROR(XLOOKUP(A15,'Shipment Setup'!$A:$A,'Shipment Setup'!$O:$O,""),""))} -> 12 | K15: =IF($A15="","",$I15*$J15) -> 0 | M15: Paid
... A101: SHP-002 | C101: =IF($A101="","",VLOOKUP($A101,'Shipment Setup'!$A:$S,2,FALSE)) -> Copenhagen | I101: =IF($A101="","",E101*VLOOKUP($A101,'Shipment Setup'!$A:$S,9,FALSE)+F101*VLOOKUP($A101,'Shipment Setup'!$A:$S,8,FALSE)+G101*VLOOKUP($A101,'Shipment Setup'!$A:$S,7,FALSE)+H101) -> 0 | J101: {=IF(A101="","",IFERROR(XLOOKUP(A101,'Shipment Setup'!$A:$A,'Shipment Setup'!$O:$O,""),""))} -> 12 | K101: =IF($A101="","",$I101*$J101) -> 0 | M101: Paid

Sheet Settlement
A1: Settlement Logic
A2: Selected Shipment ID | B2: SHP-002
A3: Shipment ID | B3: =B2 -> SHP-002
A4: Product Cost | B4: {=IF($B$3="","",XLOOKUP($B$3,'Shipment Setup'!$A:$A,'Shipment Setup'!$N:$N,""))} -> 7296
A5: Clenny Product Investment | B5: {=IF($B$3="","",XLOOKUP($B$3,'Shipment Setup'!$A:$A,'Shipment Setup'!$Q:$Q,""))} -> 501
A6: Clanny Product Investment | B6: {=IF($B$3="","",XLOOKUP($B$3,'Shipment Setup'!$A:$A,'Shipment Setup'!$R:$R,""))} -> 6795
A7: Clenny Approved Operations | B7: =SUMIFS('Operations Ledger'!E:E,'Operations Ledger'!A:A,$B$3,'Operations Ledger'!B:B,"Clenny",'Operations Ledger'!F:F,"Yes") -> 0
A8: Clanny Approved Operations | B8: =SUMIFS('Operations Ledger'!E:E,'Operations Ledger'!A:A,$B$3,'Operations Ledger'!B:B,"Clanny",'Operations Ledger'!F:F,"Yes") -> 556.86
A9: Total Operations | B9: =B7+B8 -> 556.86
A10: Total Contribution Basis | B10: =B4+B9 -> 7852.86
A12: Clenny Contribution Basis | B12: =B5+B7 -> 501
A13: Clanny Contribution Basis | B13: =B6+B8 -> 7351.86
A14: Clenny Contribution % | B14: =IF(B10=0,0,B12/B10) -> 0.063798412
A15: Clanny Contribution % | B15: =IF(B10=0,0,B13/B10) -> 0.93620159
A17: Gross Sales Entered To Date | B17: =SUMIFS('Sales Ledger'!K:K,'Sales Ledger'!A:A,$B$3) -> 0
A18: Projected Gross Revenue | B18: {=IF($B$3="","",XLOOKUP($B$3,'Shipment Setup'!$A:$A,'Shipment Setup'!$P:$P,""))} -> 12960
A19: Projected Profit After Approved Ops | B19: =B18-B10 -> 5107.14
A20: Current Profit/Loss Based On Sales To Date | B20: =B17-B10 -> -7852.86
A22: Clenny Projected Profit Share | B22: =B19*B14 -> 325.82742
A23: Clanny Projected Profit Share | B23: =B19*B15 -> 4781.3126
A24: Clenny Projected Payout | B24: =B12+B22 -> 826.82742
A25: Clanny Projected Payout | B25: =B13+B23 -> 12133.173
A27: Cash Collected by Clenny | B27: =SUMIFS('Sales Ledger'!K:K,'Sales Ledger'!A:A,$B$3,'Sales Ledger'!L:L,"Clenny") -> 0
A28: Cash Collected by Clanny | B28: =SUMIFS('Sales Ledger'!K:K,'Sales Ledger'!A:A,$B$3,'Sales Ledger'!L:L,"Clanny") -> 0
A29: Inventory Sold, Cans | B29: =SUMIFS('Sales Ledger'!I:I,'Sales Ledger'!A:A,$B$3) -> 0
A30: Inventory Remaining, Cans | B30: {=IF($B$3="",0,MAX(0,XLOOKUP($B$3,'Shipment Setup'!$A:$A,'Shipment Setup'!$L:$L,0)-B29))} -> 1080
A31: Remaining Inventory Value @ Target Price | B31: {=IF($B$3="",0,B30*XLOOKUP($B$3,'Shipment Setup'!$A:$A,'Shipment Setup'!$O:$O,0))} -> 12960
A33: Clenny Balance After All Sales Entered | B33: =B24-B27 -> 826.82742
A34: Clanny Balance After All Sales Entered | B34: =B25-B28 -> 12133.173
A36: Check: Projected Payouts - Projected Revenue | B36: =B24+B25-B18 -> 0
A37: Check: Contribution Basis | B37: =B12+B13-B10 -> 0

Sheet Rules
A1: Rules for Shipments Moving Forward
A3: Rule | B3: Meaning | C3: Where to enter it | D3: Affects settlement? | E3: Note
A4: First shipment excluded | B4: The proof-of-concept loss is not carried forward. | C4: N/A | D4: No | E4: Starting clean with SHP-002.
A5: Clenny product investment | B5: $501.00 starts as Clenny's investment for the Copenhagen shipment. | C5: Shipment Setup!Q2 | D5: Yes | E5: Editable if cash contribution changes.
A6: Clanny product investment | B6: The remainder of the product cost belongs to Clanny. | C6: Shipment Setup!R2 | D6: Yes | E6: Formula: total product cost minus Clenny investment.
A7: Own operations entered separately | B7: Clanny enters Clanny costs; Clenny enters Clenny costs. | C7: Operations Ledger | D7: Yes, only if Included = Yes | E7: Gas, rental, freight, pickup, loading, etc.
A8: No even split on operations | B8: Operational costs are not automatically split 50/50. | C8: Operations Ledger | D8: Yes | E8: Each person's approved ops increase their contribution basis.
A9: Approved business ops only | B9: Personal expenses should not be included. | C9: Operations Ledger column F | D9: Only Yes rows | E9: Do not let random lunch receipts become corporate finance.
A10: Product taken personally | B10: Enter as sale/withdrawal, not as operations. | C10: Sales Ledger | D10: Yes | E10: This prevents product taken from hiding inside operations.
A11: Final payout method | B11: Payout = contribution reimbursement + profit share. | C11: Settlement | D11: Formula driven | E11: Profit share is based on total approved contribution basis.
A12: Cash collection matters | B12: Whoever collects customer money is tracked separately. | C12: Sales Ledger column L | D12: Yes | E12: Settlement balances compare payout due versus cash held.
A13: Inventory math | B13: 2 boxes = 12 cases = 216 rolls = 1,080 cans. | C13: Shipment Setup | D13: Yes | E13: Based on 6 cases/box, 18 rolls/case, 5 cans/roll.
A14: Target sale price | B14: ="Workbook uses $"&TEXT('Shipment Setup'!O2,"0")&"/can as projected sales price." -> Workbook uses $12/can as projected sales price. | C14: Shipment Setup!O2 | D14: Yes | E14: Change this if actual selling price changes.

Sheet All Shipments Summary
A1: Shipment ID | B1: Product | C1: Status | D1: Total Product Cost | E1: Projected Revenue | F1: Gross Sales To Date | G1: Cans Sold | H1: Inventory Remaining | I1: Clenny Balance | J1: Clanny Balance | K1: Notes
A2: =IF('Shipment Setup'!A2="","",'Shipment Setup'!A2) -> SHP-002 | B2: {=IF($A2="","",XLOOKUP($A2,'Shipment Setup'!$A:$A,'Shipment Setup'!$B:$B,""))} -> Copenhagen | C2: {=IF($A2="","",XLOOKUP($A2,'Shipment Setup'!$A:$A,'Shipment Setup'!$C:$C,""))} -> In Transit | D2: {=IF($A2="","",XLOOKUP($A2,'Shipment Setup'!$A:$A,'Shipment Setup'!$N:$N,0))} -> 7296 | E2: {=IF($A2="","",XLOOKUP($A2,'Shipment Setup'!$A:$A,'Shipment Setup'!$P:$P,0))} -> 12960 | F2: =IF($A2="","",SUMIFS('Sales Ledger'!$K:$K,'Sales Ledger'!$A:$A,$A2)) -> 0 | G2: =IF($A2="","",SUMIFS('Sales Ledger'!$I:$I,'Sales Ledger'!$A:$A,$A2)) -> 0 | H2: {=IF($A2="","",MAX(0,XLOOKUP($A2,'Shipment Setup'!$A:$A,'Shipment Setup'!$L:$L,0)-G2))} -> 1080 | I2: {=IF($A2="","",(XLOOKUP($A2,'Shipment Setup'!$A:$A,'Shipment Setup'!$Q:$Q,0)+SUMIFS('Operations Ledger'!$E:$E,'Operations Ledger'!$A:$A,$A2,'Operations Ledger'!$B:$B,"Clenny",'Operations Ledger'!$F:$F,"Yes"))+((F2-(XLOOKUP($A2,'Shipment Setup'!$A:$A,'Shipment Setup'!$N:$N,0)+SUMIFS('Operations Ledger'!$E:$E,'Operations Ledger'!$A:$A,$A2,'Operations Ledger'!$F:$F,"Yes")))*IF((XLOOKUP($A2,'Shipment Setup'!$A:$A,'Shipment Setup'!$Q:$Q,0)+SUMIFS('Operations Ledger'!$E:$E,'Operations Ledger'!$A:$A,$A2,'Operations Ledger'!$B:$B,"Clenny",'Operations Ledger'!$F:$F,"Yes")+XLOOKUP($A2,'Shipment Setup'!$A:$A,'Shipment Setup'!$R:$R,0)+SUMIFS('Operations Ledger'!$E:$E,'Operations Ledger'!$A:$A,$A2,'Operations Ledger'!$B:$B,"Clanny",'Operations Ledger'!$F:$F,"Yes"))=0,0,(XLOOKUP($A2,'Shipment Setup'!$A:$A,'Shipment Setup'!$Q:$Q,0)+SUMIFS('Operations Ledger'!$E:$E,'Operations Ledger'!$A:$A,$A2,'Operations Ledger'!$B:$B,"Clenny",'Operations Ledger'!$F:$F,"Yes"))/(XLOOKUP($A2,'Shipment Setup'!$A:$A,'Shipment Setup'!$Q:$Q,0)+SUMIFS('Operations Ledger'!$E:$E,'Operations Ledger'!$A:$A,$A2,'Operations Ledger'!$B:$B,"Clenny",'Operations Ledger'!$F:$F,"Yes")+XLOOKUP($A2,'Shipment Setup'!$A:$A,'Shipment Setup'!$R:$R,0)+SUMIFS('Operations Ledger'!$E:$E,'Operations Ledger'!$A:$A,$A2,'Operations Ledger'!$B:$B,"Clanny",'Operations Ledger'!$F:$F,"Yes"))))-SUMIFS('Sales Ledger'!$K:$K,'Sales Ledger'!$A:$A,$A2,'Sales Ledger'!$L:$L,"Clenny"))} -> 0 | J2: {=IF($A2="","",(XLOOKUP($A2,'Shipment Setup'!$A:$A,'Shipment Setup'!$R:$R,0)+SUMIFS('Operations Ledger'!$E:$E,'Operations Ledger'!$A:$A,$A2,'Operations Ledger'!$B:$B,"Clanny",'Operations Ledger'!$F:$F,"Yes"))+((F2-(XLOOKUP($A2,'Shipment Setup'!$A:$A,'Shipment Setup'!$N:$N,0)+SUMIFS('Operations Ledger'!$E:$E,'Operations Ledger'!$A:$A,$A2,'Operations Ledger'!$F:$F,"Yes")))*IF((XLOOKUP($A2,'Shipment Setup'!$A:$A,'Shipment Setup'!$Q:$Q,0)+SUMIFS('Operations Ledger'!$E:$E,'Operations Ledger'!$A:$A,$A2,'Operations Ledger'!$B:$B,"Clenny",'Operations Ledger'!$F:$F,"Yes")+XLOOKUP($A2,'Shipment Setup'!$A:$A,'Shipment Setup'!$R:$R,0)+SUMIFS('Operations Ledger'!$E:$E,'Operations Ledger'!$A:$A,$A2,'Operations Ledger'!$B:$B,"Clanny",'Operations Ledger'!$F:$F,"Yes"))=0,0,(XLOOKUP($A2,'Shipment Setup'!$A:$A,'Shipment Setup'!$R:$R,0)+SUMIFS('Operations Ledger'!$E:$E,'Operations Ledger'!$A:$A,$A2,'Operations Ledger'!$B:$B,"Clanny",'Operations Ledger'!$F:$F,"Yes"))/(XLOOKUP($A2,'Shipment Setup'!$A:$A,'Shipment Setup'!$Q:$Q,0)+SUMIFS('Operations Ledger'!$E:$E,'Operations Ledger'!$A:$A,$A2,'Operations Ledger'!$B:$B,"Clenny",'Operations Ledger'!$F:$F,"Yes")+XLOOKUP($A2,'Shipment Setup'!$A:$A,'Shipment Setup'!$R:$R,0)+SUMIFS('Operations Ledger'!$E:$E,'Operations Ledger'!$A:$A,$A2,'Operations Ledger'!$B:$B,"Clanny",'Operations Ledger'!$F:$F,"Yes"))))-SUMIFS('Sales Ledger'!$K:$K,'Sales Ledger'!$A:$A,$A2,'Sales Ledger'!$L:$L,"Clanny"))} -> 0 | K2: {=IF($A2="","",XLOOKUP($A2,'Shipment Setup'!$A:$A,'Shipment Setup'!$S:$S,""))} -> Expected arrival: July 1. Base planning assumption: most cans sell at $12 each, with some possibly sold at $13.
A3: =IF('Shipment Setup'!A3="","",'Shipment Setup'!A3) -> SHP-003 | B3: {=IF($A3="","",XLOOKUP($A3,'Shipment Setup'!$A:$A,'Shipment Setup'!$B:$B,""))} -> Grizzly | C3: {=IF($A3="","",XLOOKUP($A3,'Shipment Setup'!$A:$A,'Shipment Setup'!$C:$C,""))} -> Planned | D3: {=IF($A3="","",XLOOKUP($A3,'Shipment Setup'!$A:$A,'Shipment Setup'!$N:$N,0))} -> 0 | E3: {=IF($A3="","",XLOOKUP($A3,'Shipment Setup'!$A:$A,'Shipment Setup'!$P:$P,0))} -> 0 | F3: =IF($A3="","",SUMIFS('Sales Ledger'!$K:$K,'Sales Ledger'!$A:$A,$A3)) -> 0 | G3: =IF($A3="","",SUMIFS('Sales Ledger'!$I:$I,'Sales Ledger'!$A:$A,$A3)) -> 0 | H3: {=IF($A3="","",MAX(0,XLOOKUP($A3,'Shipment Setup'!$A:$A,'Shipment Setup'!$L:$L,0)-G3))} -> 0 | I3: {=IF($A3="","",(XLOOKUP($A3,'Shipment Setup'!$A:$A,'Shipment Setup'!$Q:$Q,0)+SUMIFS('Operations Ledger'!$E:$E,'Operations Ledger'!$A:$A,$A3,'Operations Ledger'!$B:$B,"Clenny",'Operations Ledger'!$F:$F,"Yes"))+((F3-(XLOOKUP($A3,'Shipment Setup'!$A:$A,'Shipment Setup'!$N:$N,0)+SUMIFS('Operations Ledger'!$E:$E,'Operations Ledger'!$A:$A,$A3,'Operations Ledger'!$F:$F,"Yes")))*IF((XLOOKUP($A3,'Shipment Setup'!$A:$A,'Shipment Setup'!$Q:$Q,0)+SUMIFS('Operations Ledger'!$E:$E,'Operations Ledger'!$A:$A,$A3,'Operations Ledger'!$B:$B,"Clenny",'Operations Ledger'!$F:$F,"Yes")+XLOOKUP($A3,'Shipment Setup'!$A:$A,'Shipment Setup'!$R:$R,0)+SUMIFS('Operations Ledger'!$E:$E,'Operations Ledger'!$A:$A,$A3,'Operations Ledger'!$B:$B,"Clanny",'Operations Ledger'!$F:$F,"Yes"))=0,0,(XLOOKUP($A3,'Shipment Setup'!$A:$A,'Shipment Setup'!$Q:$Q,0)+SUMIFS('Operations Ledger'!$E:$E,'Operations Ledger'!$A:$A,$A3,'Operations Ledger'!$B:$B,"Clenny",'Operations Ledger'!$F:$F,"Yes"))/(XLOOKUP($A3,'Shipment Setup'!$A:$A,'Shipment Setup'!$Q:$Q,0)+SUMIFS('Operations Ledger'!$E:$E,'Operations Ledger'!$A:$A,$A3,'Operations Ledger'!$B:$B,"Clenny",'Operations Ledger'!$F:$F,"Yes")+XLOOKUP($A3,'Shipment Setup'!$A:$A,'Shipment Setup'!$R:$R,0)+SUMIFS('Operations Ledger'!$E:$E,'Operations Ledger'!$A:$A,$A3,'Operations Ledger'!$B:$B,"Clanny",'Operations Ledger'!$F:$F,"Yes"))))-SUMIFS('Sales Ledger'!$K:$K,'Sales Ledger'!$A:$A,$A3,'Sales Ledger'!$L:$L,"Clenny"))} -> 0 | J3: {=IF($A3="","",(XLOOKUP($A3,'Shipment Setup'!$A:$A,'Shipment Setup'!$R:$R,0)+SUMIFS('Operations Ledger'!$E:$E,'Operations Ledger'!$A:$A,$A3,'Operations Ledger'!$B:$B,"Clanny",'Operations Ledger'!$F:$F,"Yes"))+((F3-(XLOOKUP($A3,'Shipment Setup'!$A:$A,'Shipment Setup'!$N:$N,0)+SUMIFS('Operations Ledger'!$E:$E,'Operations Ledger'!$A:$A,$A3,'Operations Ledger'!$F:$F,"Yes")))*IF((XLOOKUP($A3,'Shipment Setup'!$A:$A,'Shipment Setup'!$Q:$Q,0)+SUMIFS('Operations Ledger'!$E:$E,'Operations Ledger'!$A:$A,$A3,'Operations Ledger'!$B:$B,"Clenny",'Operations Ledger'!$F:$F,"Yes")+XLOOKUP($A3,'Shipment Setup'!$A:$A,'Shipment Setup'!$R:$R,0)+SUMIFS('Operations Ledger'!$E:$E,'Operations Ledger'!$A:$A,$A3,'Operations Ledger'!$B:$B,"Clanny",'Operations Ledger'!$F:$F,"Yes"))=0,0,(XLOOKUP($A3,'Shipment Setup'!$A:$A,'Shipment Setup'!$R:$R,0)+SUMIFS('Operations Ledger'!$E:$E,'Operations Ledger'!$A:$A,$A3,'Operations Ledger'!$B:$B,"Clanny",'Operations Ledger'!$F:$F,"Yes"))/(XLOOKUP($A3,'Shipment Setup'!$A:$A,'Shipment Setup'!$Q:$Q,0)+SUMIFS('Operations Ledger'!$E:$E,'Operations Ledger'!$A:$A,$A3,'Operations Ledger'!$B:$B,"Clenny",'Operations Ledger'!$F:$F,"Yes")+XLOOKUP($A3,'Shipment Setup'!$A:$A,'Shipment Setup'!$R:$R,0)+SUMIFS('Operations Ledger'!$E:$E,'Operations Ledger'!$A:$A,$A3,'Operations Ledger'!$B:$B,"Clanny",'Operations Ledger'!$F:$F,"Yes"))))-SUMIFS('Sales Ledger'!$K:$K,'Sales Ledger'!$A:$A,$A3,'Sales Ledger'!$L:$L,"Clanny"))} -> 0 | K3: {=IF($A3="","",XLOOKUP($A3,'Shipment Setup'!$A:$A,'Shipment Setup'!$S:$S,""))} -> Per Clanny 7/1: Grizzly letter F, $497/case. PO guy MAJ charges $250/box starting this shipment, plus one case for himself. Boxes/case config TBD.
A4: =IF('Shipment Setup'!A4="","",'Shipment Setup'!A4) | B4: {=IF($A4="","",XLOOKUP($A4,'Shipment Setup'!$A:$A,'Shipment Setup'!$B:$B,""))} | C4: {=IF($A4="","",XLOOKUP($A4,'Shipment Setup'!$A:$A,'Shipment Setup'!$C:$C,""))} | D4: {=IF($A4="","",XLOOKUP($A4,'Shipment Setup'!$A:$A,'Shipment Setup'!$N:$N,0))} | E4: {=IF($A4="","",XLOOKUP($A4,'Shipment Setup'!$A:$A,'Shipment Setup'!$P:$P,0))} | F4: =IF($A4="","",SUMIFS('Sales Ledger'!$K:$K,'Sales Ledger'!$A:$A,$A4)) | G4: =IF($A4="","",SUMIFS('Sales Ledger'!$I:$I,'Sales Ledger'!$A:$A,$A4)) | H4: {=IF($A4="","",MAX(0,XLOOKUP($A4,'Shipment Setup'!$A:$A,'Shipment Setup'!$L:$L,0)-G4))} | I4: {=IF($A4="","",(XLOOKUP($A4,'Shipment Setup'!$A:$A,'Shipment Setup'!$Q:$Q,0)+SUMIFS('Operations Ledger'!$E:$E,'Operations Ledger'!$A:$A,$A4,'Operations Ledger'!$B:$B,"Clenny",'Operations Ledger'!$F:$F,"Yes"))+((F4-(XLOOKUP($A4,'Shipment Setup'!$A:$A,'Shipment Setup'!$N:$N,0)+SUMIFS('Operations Ledger'!$E:$E,'Operations Ledger'!$A:$A,$A4,'Operations Ledger'!$F:$F,"Yes")))*IF((XLOOKUP($A4,'Shipment Setup'!$A:$A,'Shipment Setup'!$Q:$Q,0)+SUMIFS('Operations Ledger'!$E:$E,'Operations Ledger'!$A:$A,$A4,'Operations Ledger'!$B:$B,"Clenny",'Operations Ledger'!$F:$F,"Yes")+XLOOKUP($A4,'Shipment Setup'!$A:$A,'Shipment Setup'!$R:$R,0)+SUMIFS('Operations Ledger'!$E:$E,'Operations Ledger'!$A:$A,$A4,'Operations Ledger'!$B:$B,"Clanny",'Operations Ledger'!$F:$F,"Yes"))=0,0,(XLOOKUP($A4,'Shipment Setup'!$A:$A,'Shipment Setup'!$Q:$Q,0)+SUMIFS('Operations Ledger'!$E:$E,'Operations Ledger'!$A:$A,$A4,'Operations Ledger'!$B:$B,"Clenny",'Operations Ledger'!$F:$F,"Yes"))/(XLOOKUP($A4,'Shipment Setup'!$A:$A,'Shipment Setup'!$Q:$Q,0)+SUMIFS('Operations Ledger'!$E:$E,'Operations Ledger'!$A:$A,$A4,'Operations Ledger'!$B:$B,"Clenny",'Operations Ledger'!$F:$F,"Yes")+XLOOKUP($A4,'Shipment Setup'!$A:$A,'Shipment Setup'!$R:$R,0)+SUMIFS('Operations Ledger'!$E:$E,'Operations Ledger'!$A:$A,$A4,'Operations Ledger'!$B:$B,"Clanny",'Operations Ledger'!$F:$F,"Yes"))))-SUMIFS('Sales Ledger'!$K:$K,'Sales Ledger'!$A:$A,$A4,'Sales Ledger'!$L:$L,"Clenny"))} | J4: {=IF($A4="","",(XLOOKUP($A4,'Shipment Setup'!$A:$A,'Shipment Setup'!$R:$R,0)+SUMIFS('Operations Ledger'!$E:$E,'Operations Ledger'!$A:$A,$A4,'Operations Ledger'!$B:$B,"Clanny",'Operations Ledger'!$F:$F,"Yes"))+((F4-(XLOOKUP($A4,'Shipment Setup'!$A:$A,'Shipment Setup'!$N:$N,0)+SUMIFS('Operations Ledger'!$E:$E,'Operations Ledger'!$A:$A,$A4,'Operations Ledger'!$F:$F,"Yes")))*IF((XLOOKUP($A4,'Shipment Setup'!$A:$A,'Shipment Setup'!$Q:$Q,0)+SUMIFS('Operations Ledger'!$E:$E,'Operations Ledger'!$A:$A,$A4,'Operations Ledger'!$B:$B,"Clenny",'Operations Ledger'!$F:$F,"Yes")+XLOOKUP($A4,'Shipment Setup'!$A:$A,'Shipment Setup'!$R:$R,0)+SUMIFS('Operations Ledger'!$E:$E,'Operations Ledger'!$A:$A,$A4,'Operations Ledger'!$B:$B,"Clanny",'Operations Ledger'!$F:$F,"Yes"))=0,0,(XLOOKUP($A4,'Shipment Setup'!$A:$A,'Shipment Setup'!$R:$R,0)+SUMIFS('Operations Ledger'!$E:$E,'Operations Ledger'!$A:$A,$A4,'Operations Ledger'!$B:$B,"Clanny",'Operations Ledger'!$F:$F,"Yes"))/(XLOOKUP($A4,'Shipment Setup'!$A:$A,'Shipment Setup'!$Q:$Q,0)+SUMIFS('Operations Ledger'!$E:$E,'Operations Ledger'!$A:$A,$A4,'Operations Ledger'!$B:$B,"Clenny",'Operations Ledger'!$F:$F,"Yes")+XLOOKUP($A4,'Shipment Setup'!$A:$A,'Shipment Setup'!$R:$R,0)+SUMIFS('Operations Ledger'!$E:$E,'Operations Ledger'!$A:$A,$A4,'Operations Ledger'!$B:$B,"Clanny",'Operations Ledger'!$F:$F,"Yes"))))-SUMIFS('Sales Ledger'!$K:$K,'Sales Ledger'!$A:$A,$A4,'Sales Ledger'!$L:$L,"Clanny"))} | K4: {=IF($A4="","",XLOOKUP($A4,'Shipment Setup'!$A:$A,'Shipment Setup'!$S:$S,""))}
A5: =IF('Shipment Setup'!A5="","",'Shipment Setup'!A5) | B5: {=IF($A5="","",XLOOKUP($A5,'Shipment Setup'!$A:$A,'Shipment Setup'!$B:$B,""))} | C5: {=IF($A5="","",XLOOKUP($A5,'Shipment Setup'!$A:$A,'Shipment Setup'!$C:$C,""))} | D5: {=IF($A5="","",XLOOKUP($A5,'Shipment Setup'!$A:$A,'Shipment Setup'!$N:$N,0))} | E5: {=IF($A5="","",XLOOKUP($A5,'Shipment Setup'!$A:$A,'Shipment Setup'!$P:$P,0))} | F5: =IF($A5="","",SUMIFS('Sales Ledger'!$K:$K,'Sales Ledger'!$A:$A,$A5)) | G5: =IF($A5="","",SUMIFS('Sales Ledger'!$I:$I,'Sales Ledger'!$A:$A,$A5)) | H5: {=IF($A5="","",MAX(0,XLOOKUP($A5,'Shipment Setup'!$A:$A,'Shipment Setup'!$L:$L,0)-G5))} | I5: {=IF($A5="","",(XLOOKUP($A5,'Shipment Setup'!$A:$A,'Shipment Setup'!$Q:$Q,0)+SUMIFS('Operations Ledger'!$E:$E,'Operations Ledger'!$A:$A,$A5,'Operations Ledger'!$B:$B,"Clenny",'Operations Ledger'!$F:$F,"Yes"))+((F5-(XLOOKUP($A5,'Shipment Setup'!$A:$A,'Shipment Setup'!$N:$N,0)+SUMIFS('Operations Ledger'!$E:$E,'Operations Ledger'!$A:$A,$A5,'Operations Ledger'!$F:$F,"Yes")))*IF((XLOOKUP($A5,'Shipment Setup'!$A:$A,'Shipment Setup'!$Q:$Q,0)+SUMIFS('Operations Ledger'!$E:$E,'Operations Ledger'!$A:$A,$A5,'Operations Ledger'!$B:$B,"Clenny",'Operations Ledger'!$F:$F,"Yes")+XLOOKUP($A5,'Shipment Setup'!$A:$A,'Shipment Setup'!$R:$R,0)+SUMIFS('Operations Ledger'!$E:$E,'Operations Ledger'!$A:$A,$A5,'Operations Ledger'!$B:$B,"Clanny",'Operations Ledger'!$F:$F,"Yes"))=0,0,(XLOOKUP($A5,'Shipment Setup'!$A:$A,'Shipment Setup'!$Q:$Q,0)+SUMIFS('Operations Ledger'!$E:$E,'Operations Ledger'!$A:$A,$A5,'Operations Ledger'!$B:$B,"Clenny",'Operations Ledger'!$F:$F,"Yes"))/(XLOOKUP($A5,'Shipment Setup'!$A:$A,'Shipment Setup'!$Q:$Q,0)+SUMIFS('Operations Ledger'!$E:$E,'Operations Ledger'!$A:$A,$A5,'Operations Ledger'!$B:$B,"Clenny",'Operations Ledger'!$F:$F,"Yes")+XLOOKUP($A5,'Shipment Setup'!$A:$A,'Shipment Setup'!$R:$R,0)+SUMIFS('Operations Ledger'!$E:$E,'Operations Ledger'!$A:$A,$A5,'Operations Ledger'!$B:$B,"Clanny",'Operations Ledger'!$F:$F,"Yes"))))-SUMIFS('Sales Ledger'!$K:$K,'Sales Ledger'!$A:$A,$A5,'Sales Ledger'!$L:$L,"Clenny"))} | J5: {=IF($A5="","",(XLOOKUP($A5,'Shipment Setup'!$A:$A,'Shipment Setup'!$R:$R,0)+SUMIFS('Operations Ledger'!$E:$E,'Operations Ledger'!$A:$A,$A5,'Operations Ledger'!$B:$B,"Clanny",'Operations Ledger'!$F:$F,"Yes"))+((F5-(XLOOKUP($A5,'Shipment Setup'!$A:$A,'Shipment Setup'!$N:$N,0)+SUMIFS('Operations Ledger'!$E:$E,'Operations Ledger'!$A:$A,$A5,'Operations Ledger'!$F:$F,"Yes")))*IF((XLOOKUP($A5,'Shipment Setup'!$A:$A,'Shipment Setup'!$Q:$Q,0)+SUMIFS('Operations Ledger'!$E:$E,'Operations Ledger'!$A:$A,$A5,'Operations Ledger'!$B:$B,"Clenny",'Operations Ledger'!$F:$F,"Yes")+XLOOKUP($A5,'Shipment Setup'!$A:$A,'Shipment Setup'!$R:$R,0)+SUMIFS('Operations Ledger'!$E:$E,'Operations Ledger'!$A:$A,$A5,'Operations Ledger'!$B:$B,"Clanny",'Operations Ledger'!$F:$F,"Yes"))=0,0,(XLOOKUP($A5,'Shipment Setup'!$A:$A,'Shipment Setup'!$R:$R,0)+SUMIFS('Operations Ledger'!$E:$E,'Operations Ledger'!$A:$A,$A5,'Operations Ledger'!$B:$B,"Clanny",'Operations Ledger'!$F:$F,"Yes"))/(XLOOKUP($A5,'Shipment Setup'!$A:$A,'Shipment Setup'!$Q:$Q,0)+SUMIFS('Operations Ledger'!$E:$E,'Operations Ledger'!$A:$A,$A5,'Operations Ledger'!$B:$B,"Clenny",'Operations Ledger'!$F:$F,"Yes")+XLOOKUP($A5,'Shipment Setup'!$A:$A,'Shipment Setup'!$R:$R,0)+SUMIFS('Operations Ledger'!$E:$E,'Operations Ledger'!$A:$A,$A5,'Operations Ledger'!$B:$B,"Clanny",'Operations Ledger'!$F:$F,"Yes"))))-SUMIFS('Sales Ledger'!$K:$K,'Sales Ledger'!$A:$A,$A5,'Sales Ledger'!$L:$L,"Clanny"))} | K5: {=IF($A5="","",XLOOKUP($A5,'Shipment Setup'!$A:$A,'Shipment Setup'!$S:$S,""))}
A6: =IF('Shipment Setup'!A6="","",'Shipment Setup'!A6) | B6: {=IF($A6="","",XLOOKUP($A6,'Shipment Setup'!$A:$A,'Shipment Setup'!$B:$B,""))} | C6: {=IF($A6="","",XLOOKUP($A6,'Shipment Setup'!$A:$A,'Shipment Setup'!$C:$C,""))} | D6: {=IF($A6="","",XLOOKUP($A6,'Shipment Setup'!$A:$A,'Shipment Setup'!$N:$N,0))} | E6: {=IF($A6="","",XLOOKUP($A6,'Shipment Setup'!$A:$A,'Shipment Setup'!$P:$P,0))} | F6: =IF($A6="","",SUMIFS('Sales Ledger'!$K:$K,'Sales Ledger'!$A:$A,$A6)) | G6: =IF($A6="","",SUMIFS('Sales Ledger'!$I:$I,'Sales Ledger'!$A:$A,$A6)) | H6: {=IF($A6="","",MAX(0,XLOOKUP($A6,'Shipment Setup'!$A:$A,'Shipment Setup'!$L:$L,0)-G6))} | I6: {=IF($A6="","",(XLOOKUP($A6,'Shipment Setup'!$A:$A,'Shipment Setup'!$Q:$Q,0)+SUMIFS('Operations Ledger'!$E:$E,'Operations Ledger'!$A:$A,$A6,'Operations Ledger'!$B:$B,"Clenny",'Operations Ledger'!$F:$F,"Yes"))+((F6-(XLOOKUP($A6,'Shipment Setup'!$A:$A,'Shipment Setup'!$N:$N,0)+SUMIFS('Operations Ledger'!$E:$E,'Operations Ledger'!$A:$A,$A6,'Operations Ledger'!$F:$F,"Yes")))*IF((XLOOKUP($A6,'Shipment Setup'!$A:$A,'Shipment Setup'!$Q:$Q,0)+SUMIFS('Operations Ledger'!$E:$E,'Operations Ledger'!$A:$A,$A6,'Operations Ledger'!$B:$B,"Clenny",'Operations Ledger'!$F:$F,"Yes")+XLOOKUP($A6,'Shipment Setup'!$A:$A,'Shipment Setup'!$R:$R,0)+SUMIFS('Operations Ledger'!$E:$E,'Operations Ledger'!$A:$A,$A6,'Operations Ledger'!$B:$B,"Clanny",'Operations Ledger'!$F:$F,"Yes"))=0,0,(XLOOKUP($A6,'Shipment Setup'!$A:$A,'Shipment Setup'!$Q:$Q,0)+SUMIFS('Operations Ledger'!$E:$E,'Operations Ledger'!$A:$A,$A6,'Operations Ledger'!$B:$B,"Clenny",'Operations Ledger'!$F:$F,"Yes"))/(XLOOKUP($A6,'Shipment Setup'!$A:$A,'Shipment Setup'!$Q:$Q,0)+SUMIFS('Operations Ledger'!$E:$E,'Operations Ledger'!$A:$A,$A6,'Operations Ledger'!$B:$B,"Clenny",'Operations Ledger'!$F:$F,"Yes")+XLOOKUP($A6,'Shipment Setup'!$A:$A,'Shipment Setup'!$R:$R,0)+SUMIFS('Operations Ledger'!$E:$E,'Operations Ledger'!$A:$A,$A6,'Operations Ledger'!$B:$B,"Clanny",'Operations Ledger'!$F:$F,"Yes"))))-SUMIFS('Sales Ledger'!$K:$K,'Sales Ledger'!$A:$A,$A6,'Sales Ledger'!$L:$L,"Clenny"))} | J6: {=IF($A6="","",(XLOOKUP($A6,'Shipment Setup'!$A:$A,'Shipment Setup'!$R:$R,0)+SUMIFS('Operations Ledger'!$E:$E,'Operations Ledger'!$A:$A,$A6,'Operations Ledger'!$B:$B,"Clanny",'Operations Ledger'!$F:$F,"Yes"))+((F6-(XLOOKUP($A6,'Shipment Setup'!$A:$A,'Shipment Setup'!$N:$N,0)+SUMIFS('Operations Ledger'!$E:$E,'Operations Ledger'!$A:$A,$A6,'Operations Ledger'!$F:$F,"Yes")))*IF((XLOOKUP($A6,'Shipment Setup'!$A:$A,'Shipment Setup'!$Q:$Q,0)+SUMIFS('Operations Ledger'!$E:$E,'Operations Ledger'!$A:$A,$A6,'Operations Ledger'!$B:$B,"Clenny",'Operations Ledger'!$F:$F,"Yes")+XLOOKUP($A6,'Shipment Setup'!$A:$A,'Shipment Setup'!$R:$R,0)+SUMIFS('Operations Ledger'!$E:$E,'Operations Ledger'!$A:$A,$A6,'Operations Ledger'!$B:$B,"Clanny",'Operations Ledger'!$F:$F,"Yes"))=0,0,(XLOOKUP($A6,'Shipment Setup'!$A:$A,'Shipment Setup'!$R:$R,0)+SUMIFS('Operations Ledger'!$E:$E,'Operations Ledger'!$A:$A,$A6,'Operations Ledger'!$B:$B,"Clanny",'Operations Ledger'!$F:$F,"Yes"))/(XLOOKUP($A6,'Shipment Setup'!$A:$A,'Shipment Setup'!$Q:$Q,0)+SUMIFS('Operations Ledger'!$E:$E,'Operations Ledger'!$A:$A,$A6,'Operations Ledger'!$B:$B,"Clenny",'Operations Ledger'!$F:$F,"Yes")+XLOOKUP($A6,'Shipment Setup'!$A:$A,'Shipment Setup'!$R:$R,0)+SUMIFS('Operations Ledger'!$E:$E,'Operations Ledger'!$A:$A,$A6,'Operations Ledger'!$B:$B,"Clanny",'Operations Ledger'!$F:$F,"Yes"))))-SUMIFS('Sales Ledger'!$K:$K,'Sales Ledger'!$A:$A,$A6,'Sales Ledger'!$L:$L,"Clanny"))} | K6: {=IF($A6="","",XLOOKUP($A6,'Shipment Setup'!$A:$A,'Shipment Setup'!$S:$S,""))}
A7: =IF('Shipment Setup'!A7="","",'Shipment Setup'!A7) | B7: {=IF($A7="","",XLOOKUP($A7,'Shipment Setup'!$A:$A,'Shipment Setup'!$B:$B,""))} | C7: {=IF($A7="","",XLOOKUP($A7,'Shipment Setup'!$A:$A,'Shipment Setup'!$C:$C,""))} | D7: {=IF($A7="","",XLOOKUP($A7,'Shipment Setup'!$A:$A,'Shipment Setup'!$N:$N,0))} | E7: {=IF($A7="","",XLOOKUP($A7,'Shipment Setup'!$A:$A,'Shipment Setup'!$P:$P,0))} | F7: =IF($A7="","",SUMIFS('Sales Ledger'!$K:$K,'Sales Ledger'!$A:$A,$A7)) | G7: =IF($A7="","",SUMIFS('Sales Ledger'!$I:$I,'Sales Ledger'!$A:$A,$A7)) | H7: {=IF($A7="","",MAX(0,XLOOKUP($A7,'Shipment Setup'!$A:$A,'Shipment Setup'!$L:$L,0)-G7))} | I7: {=IF($A7="","",(XLOOKUP($A7,'Shipment Setup'!$A:$A,'Shipment Setup'!$Q:$Q,0)+SUMIFS('Operations Ledger'!$E:$E,'Operations Ledger'!$A:$A,$A7,'Operations Ledger'!$B:$B,"Clenny",'Operations Ledger'!$F:$F,"Yes"))+((F7-(XLOOKUP($A7,'Shipment Setup'!$A:$A,'Shipment Setup'!$N:$N,0)+SUMIFS('Operations Ledger'!$E:$E,'Operations Ledger'!$A:$A,$A7,'Operations Ledger'!$F:$F,"Yes")))*IF((XLOOKUP($A7,'Shipment Setup'!$A:$A,'Shipment Setup'!$Q:$Q,0)+SUMIFS('Operations Ledger'!$E:$E,'Operations Ledger'!$A:$A,$A7,'Operations Ledger'!$B:$B,"Clenny",'Operations Ledger'!$F:$F,"Yes")+XLOOKUP($A7,'Shipment Setup'!$A:$A,'Shipment Setup'!$R:$R,0)+SUMIFS('Operations Ledger'!$E:$E,'Operations Ledger'!$A:$A,$A7,'Operations Ledger'!$B:$B,"Clanny",'Operations Ledger'!$F:$F,"Yes"))=0,0,(XLOOKUP($A7,'Shipment Setup'!$A:$A,'Shipment Setup'!$Q:$Q,0)+SUMIFS('Operations Ledger'!$E:$E,'Operations Ledger'!$A:$A,$A7,'Operations Ledger'!$B:$B,"Clenny",'Operations Ledger'!$F:$F,"Yes"))/(XLOOKUP($A7,'Shipment Setup'!$A:$A,'Shipment Setup'!$Q:$Q,0)+SUMIFS('Operations Ledger'!$E:$E,'Operations Ledger'!$A:$A,$A7,'Operations Ledger'!$B:$B,"Clenny",'Operations Ledger'!$F:$F,"Yes")+XLOOKUP($A7,'Shipment Setup'!$A:$A,'Shipment Setup'!$R:$R,0)+SUMIFS('Operations Ledger'!$E:$E,'Operations Ledger'!$A:$A,$A7,'Operations Ledger'!$B:$B,"Clanny",'Operations Ledger'!$F:$F,"Yes"))))-SUMIFS('Sales Ledger'!$K:$K,'Sales Ledger'!$A:$A,$A7,'Sales Ledger'!$L:$L,"Clenny"))} | J7: {=IF($A7="","",(XLOOKUP($A7,'Shipment Setup'!$A:$A,'Shipment Setup'!$R:$R,0)+SUMIFS('Operations Ledger'!$E:$E,'Operations Ledger'!$A:$A,$A7,'Operations Ledger'!$B:$B,"Clanny",'Operations Ledger'!$F:$F,"Yes"))+((F7-(XLOOKUP($A7,'Shipment Setup'!$A:$A,'Shipment Setup'!$N:$N,0)+SUMIFS('Operations Ledger'!$E:$E,'Operations Ledger'!$A:$A,$A7,'Operations Ledger'!$F:$F,"Yes")))*IF((XLOOKUP($A7,'Shipment Setup'!$A:$A,'Shipment Setup'!$Q:$Q,0)+SUMIFS('Operations Ledger'!$E:$E,'Operations Ledger'!$A:$A,$A7,'Operations Ledger'!$B:$B,"Clenny",'Operations Ledger'!$F:$F,"Yes")+XLOOKUP($A7,'Shipment Setup'!$A:$A,'Shipment Setup'!$R:$R,0)+SUMIFS('Operations Ledger'!$E:$E,'Operations Ledger'!$A:$A,$A7,'Operations Ledger'!$B:$B,"Clanny",'Operations Ledger'!$F:$F,"Yes"))=0,0,(XLOOKUP($A7,'Shipment Setup'!$A:$A,'Shipment Setup'!$R:$R,0)+SUMIFS('Operations Ledger'!$E:$E,'Operations Ledger'!$A:$A,$A7,'Operations Ledger'!$B:$B,"Clanny",'Operations Ledger'!$F:$F,"Yes"))/(XLOOKUP($A7,'Shipment Setup'!$A:$A,'Shipment Setup'!$Q:$Q,0)+SUMIFS('Operations Ledger'!$E:$E,'Operations Ledger'!$A:$A,$A7,'Operations Ledger'!$B:$B,"Clenny",'Operations Ledger'!$F:$F,"Yes")+XLOOKUP($A7,'Shipment Setup'!$A:$A,'Shipment Setup'!$R:$R,0)+SUMIFS('Operations Ledger'!$E:$E,'Operations Ledger'!$A:$A,$A7,'Operations Ledger'!$B:$B,"Clanny",'Operations Ledger'!$F:$F,"Yes"))))-SUMIFS('Sales Ledger'!$K:$K,'Sales Ledger'!$A:$A,$A7,'Sales Ledger'!$L:$L,"Clanny"))} | K7: {=IF($A7="","",XLOOKUP($A7,'Shipment Setup'!$A:$A,'Shipment Setup'!$S:$S,""))}
A8: =IF('Shipment Setup'!A8="","",'Shipment Setup'!A8) | B8: {=IF($A8="","",XLOOKUP($A8,'Shipment Setup'!$A:$A,'Shipment Setup'!$B:$B,""))} | C8: {=IF($A8="","",XLOOKUP($A8,'Shipment Setup'!$A:$A,'Shipment Setup'!$C:$C,""))} | D8: {=IF($A8="","",XLOOKUP($A8,'Shipment Setup'!$A:$A,'Shipment Setup'!$N:$N,0))} | E8: {=IF($A8="","",XLOOKUP($A8,'Shipment Setup'!$A:$A,'Shipment Setup'!$P:$P,0))} | F8: =IF($A8="","",SUMIFS('Sales Ledger'!$K:$K,'Sales Ledger'!$A:$A,$A8)) | G8: =IF($A8="","",SUMIFS('Sales Ledger'!$I:$I,'Sales Ledger'!$A:$A,$A8)) | H8: {=IF($A8="","",MAX(0,XLOOKUP($A8,'Shipment Setup'!$A:$A,'Shipment Setup'!$L:$L,0)-G8))} | I8: {=IF($A8="","",(XLOOKUP($A8,'Shipment Setup'!$A:$A,'Shipment Setup'!$Q:$Q,0)+SUMIFS('Operations Ledger'!$E:$E,'Operations Ledger'!$A:$A,$A8,'Operations Ledger'!$B:$B,"Clenny",'Operations Ledger'!$F:$F,"Yes"))+((F8-(XLOOKUP($A8,'Shipment Setup'!$A:$A,'Shipment Setup'!$N:$N,0)+SUMIFS('Operations Ledger'!$E:$E,'Operations Ledger'!$A:$A,$A8,'Operations Ledger'!$F:$F,"Yes")))*IF((XLOOKUP($A8,'Shipment Setup'!$A:$A,'Shipment Setup'!$Q:$Q,0)+SUMIFS('Operations Ledger'!$E:$E,'Operations Ledger'!$A:$A,$A8,'Operations Ledger'!$B:$B,"Clenny",'Operations Ledger'!$F:$F,"Yes")+XLOOKUP($A8,'Shipment Setup'!$A:$A,'Shipment Setup'!$R:$R,0)+SUMIFS('Operations Ledger'!$E:$E,'Operations Ledger'!$A:$A,$A8,'Operations Ledger'!$B:$B,"Clanny",'Operations Ledger'!$F:$F,"Yes"))=0,0,(XLOOKUP($A8,'Shipment Setup'!$A:$A,'Shipment Setup'!$Q:$Q,0)+SUMIFS('Operations Ledger'!$E:$E,'Operations Ledger'!$A:$A,$A8,'Operations Ledger'!$B:$B,"Clenny",'Operations Ledger'!$F:$F,"Yes"))/(XLOOKUP($A8,'Shipment Setup'!$A:$A,'Shipment Setup'!$Q:$Q,0)+SUMIFS('Operations Ledger'!$E:$E,'Operations Ledger'!$A:$A,$A8,'Operations Ledger'!$B:$B,"Clenny",'Operations Ledger'!$F:$F,"Yes")+XLOOKUP($A8,'Shipment Setup'!$A:$A,'Shipment Setup'!$R:$R,0)+SUMIFS('Operations Ledger'!$E:$E,'Operations Ledger'!$A:$A,$A8,'Operations Ledger'!$B:$B,"Clanny",'Operations Ledger'!$F:$F,"Yes"))))-SUMIFS('Sales Ledger'!$K:$K,'Sales Ledger'!$A:$A,$A8,'Sales Ledger'!$L:$L,"Clenny"))} | J8: {=IF($A8="","",(XLOOKUP($A8,'Shipment Setup'!$A:$A,'Shipment Setup'!$R:$R,0)+SUMIFS('Operations Ledger'!$E:$E,'Operations Ledger'!$A:$A,$A8,'Operations Ledger'!$B:$B,"Clanny",'Operations Ledger'!$F:$F,"Yes"))+((F8-(XLOOKUP($A8,'Shipment Setup'!$A:$A,'Shipment Setup'!$N:$N,0)+SUMIFS('Operations Ledger'!$E:$E,'Operations Ledger'!$A:$A,$A8,'Operations Ledger'!$F:$F,"Yes")))*IF((XLOOKUP($A8,'Shipment Setup'!$A:$A,'Shipment Setup'!$Q:$Q,0)+SUMIFS('Operations Ledger'!$E:$E,'Operations Ledger'!$A:$A,$A8,'Operations Ledger'!$B:$B,"Clenny",'Operations Ledger'!$F:$F,"Yes")+XLOOKUP($A8,'Shipment Setup'!$A:$A,'Shipment Setup'!$R:$R,0)+SUMIFS('Operations Ledger'!$E:$E,'Operations Ledger'!$A:$A,$A8,'Operations Ledger'!$B:$B,"Clanny",'Operations Ledger'!$F:$F,"Yes"))=0,0,(XLOOKUP($A8,'Shipment Setup'!$A:$A,'Shipment Setup'!$R:$R,0)+SUMIFS('Operations Ledger'!$E:$E,'Operations Ledger'!$A:$A,$A8,'Operations Ledger'!$B:$B,"Clanny",'Operations Ledger'!$F:$F,"Yes"))/(XLOOKUP($A8,'Shipment Setup'!$A:$A,'Shipment Setup'!$Q:$Q,0)+SUMIFS('Operations Ledger'!$E:$E,'Operations Ledger'!$A:$A,$A8,'Operations Ledger'!$B:$B,"Clenny",'Operations Ledger'!$F:$F,"Yes")+XLOOKUP($A8,'Shipment Setup'!$A:$A,'Shipment Setup'!$R:$R,0)+SUMIFS('Operations Ledger'!$E:$E,'Operations Ledger'!$A:$A,$A8,'Operations Ledger'!$B:$B,"Clanny",'Operations Ledger'!$F:$F,"Yes"))))-SUMIFS('Sales Ledger'!$K:$K,'Sales Ledger'!$A:$A,$A8,'Sales Ledger'!$L:$L,"Clanny"))} | K8: {=IF($A8="","",XLOOKUP($A8,'Shipment Setup'!$A:$A,'Shipment Setup'!$S:$S,""))}
A9: =IF('Shipment Setup'!A9="","",'Shipment Setup'!A9) | B9: {=IF($A9="","",XLOOKUP($A9,'Shipment Setup'!$A:$A,'Shipment Setup'!$B:$B,""))} | C9: {=IF($A9="","",XLOOKUP($A9,'Shipment Setup'!$A:$A,'Shipment Setup'!$C:$C,""))} | D9: {=IF($A9="","",XLOOKUP($A9,'Shipment Setup'!$A:$A,'Shipment Setup'!$N:$N,0))} | E9: {=IF($A9="","",XLOOKUP($A9,'Shipment Setup'!$A:$A,'Shipment Setup'!$P:$P,0))} | F9: =IF($A9="","",SUMIFS('Sales Ledger'!$K:$K,'Sales Ledger'!$A:$A,$A9)) | G9: =IF($A9="","",SUMIFS('Sales Ledger'!$I:$I,'Sales Ledger'!$A:$A,$A9)) | H9: {=IF($A9="","",MAX(0,XLOOKUP($A9,'Shipment Setup'!$A:$A,'Shipment Setup'!$L:$L,0)-G9))} | I9: {=IF($A9="","",(XLOOKUP($A9,'Shipment Setup'!$A:$A,'Shipment Setup'!$Q:$Q,0)+SUMIFS('Operations Ledger'!$E:$E,'Operations Ledger'!$A:$A,$A9,'Operations Ledger'!$B:$B,"Clenny",'Operations Ledger'!$F:$F,"Yes"))+((F9-(XLOOKUP($A9,'Shipment Setup'!$A:$A,'Shipment Setup'!$N:$N,0)+SUMIFS('Operations Ledger'!$E:$E,'Operations Ledger'!$A:$A,$A9,'Operations Ledger'!$F:$F,"Yes")))*IF((XLOOKUP($A9,'Shipment Setup'!$A:$A,'Shipment Setup'!$Q:$Q,0)+SUMIFS('Operations Ledger'!$E:$E,'Operations Ledger'!$A:$A,$A9,'Operations Ledger'!$B:$B,"Clenny",'Operations Ledger'!$F:$F,"Yes")+XLOOKUP($A9,'Shipment Setup'!$A:$A,'Shipment Setup'!$R:$R,0)+SUMIFS('Operations Ledger'!$E:$E,'Operations Ledger'!$A:$A,$A9,'Operations Ledger'!$B:$B,"Clanny",'Operations Ledger'!$F:$F,"Yes"))=0,0,(XLOOKUP($A9,'Shipment Setup'!$A:$A,'Shipment Setup'!$Q:$Q,0)+SUMIFS('Operations Ledger'!$E:$E,'Operations Ledger'!$A:$A,$A9,'Operations Ledger'!$B:$B,"Clenny",'Operations Ledger'!$F:$F,"Yes"))/(XLOOKUP($A9,'Shipment Setup'!$A:$A,'Shipment Setup'!$Q:$Q,0)+SUMIFS('Operations Ledger'!$E:$E,'Operations Ledger'!$A:$A,$A9,'Operations Ledger'!$B:$B,"Clenny",'Operations Ledger'!$F:$F,"Yes")+XLOOKUP($A9,'Shipment Setup'!$A:$A,'Shipment Setup'!$R:$R,0)+SUMIFS('Operations Ledger'!$E:$E,'Operations Ledger'!$A:$A,$A9,'Operations Ledger'!$B:$B,"Clanny",'Operations Ledger'!$F:$F,"Yes"))))-SUMIFS('Sales Ledger'!$K:$K,'Sales Ledger'!$A:$A,$A9,'Sales Ledger'!$L:$L,"Clenny"))} | J9: {=IF($A9="","",(XLOOKUP($A9,'Shipment Setup'!$A:$A,'Shipment Setup'!$R:$R,0)+SUMIFS('Operations Ledger'!$E:$E,'Operations Ledger'!$A:$A,$A9,'Operations Ledger'!$B:$B,"Clanny",'Operations Ledger'!$F:$F,"Yes"))+((F9-(XLOOKUP($A9,'Shipment Setup'!$A:$A,'Shipment Setup'!$N:$N,0)+SUMIFS('Operations Ledger'!$E:$E,'Operations Ledger'!$A:$A,$A9,'Operations Ledger'!$F:$F,"Yes")))*IF((XLOOKUP($A9,'Shipment Setup'!$A:$A,'Shipment Setup'!$Q:$Q,0)+SUMIFS('Operations Ledger'!$E:$E,'Operations Ledger'!$A:$A,$A9,'Operations Ledger'!$B:$B,"Clenny",'Operations Ledger'!$F:$F,"Yes")+XLOOKUP($A9,'Shipment Setup'!$A:$A,'Shipment Setup'!$R:$R,0)+SUMIFS('Operations Ledger'!$E:$E,'Operations Ledger'!$A:$A,$A9,'Operations Ledger'!$B:$B,"Clanny",'Operations Ledger'!$F:$F,"Yes"))=0,0,(XLOOKUP($A9,'Shipment Setup'!$A:$A,'Shipment Setup'!$R:$R,0)+SUMIFS('Operations Ledger'!$E:$E,'Operations Ledger'!$A:$A,$A9,'Operations Ledger'!$B:$B,"Clanny",'Operations Ledger'!$F:$F,"Yes"))/(XLOOKUP($A9,'Shipment Setup'!$A:$A,'Shipment Setup'!$Q:$Q,0)+SUMIFS('Operations Ledger'!$E:$E,'Operations Ledger'!$A:$A,$A9,'Operations Ledger'!$B:$B,"Clenny",'Operations Ledger'!$F:$F,"Yes")+XLOOKUP($A9,'Shipment Setup'!$A:$A,'Shipment Setup'!$R:$R,0)+SUMIFS('Operations Ledger'!$E:$E,'Operations Ledger'!$A:$A,$A9,'Operations Ledger'!$B:$B,"Clanny",'Operations Ledger'!$F:$F,"Yes"))))-SUMIFS('Sales Ledger'!$K:$K,'Sales Ledger'!$A:$A,$A9,'Sales Ledger'!$L:$L,"Clanny"))} | K9: {=IF($A9="","",XLOOKUP($A9,'Shipment Setup'!$A:$A,'Shipment Setup'!$S:$S,""))}
A10: =IF('Shipment Setup'!A10="","",'Shipment Setup'!A10) | B10: {=IF($A10="","",XLOOKUP($A10,'Shipment Setup'!$A:$A,'Shipment Setup'!$B:$B,""))} | C10: {=IF($A10="","",XLOOKUP($A10,'Shipment Setup'!$A:$A,'Shipment Setup'!$C:$C,""))} | D10: {=IF($A10="","",XLOOKUP($A10,'Shipment Setup'!$A:$A,'Shipment Setup'!$N:$N,0))} | E10: {=IF($A10="","",XLOOKUP($A10,'Shipment Setup'!$A:$A,'Shipment Setup'!$P:$P,0))} | F10: =IF($A10="","",SUMIFS('Sales Ledger'!$K:$K,'Sales Ledger'!$A:$A,$A10)) | G10: =IF($A10="","",SUMIFS('Sales Ledger'!$I:$I,'Sales Ledger'!$A:$A,$A10)) | H10: {=IF($A10="","",MAX(0,XLOOKUP($A10,'Shipment Setup'!$A:$A,'Shipment Setup'!$L:$L,0)-G10))} | I10: {=IF($A10="","",(XLOOKUP($A10,'Shipment Setup'!$A:$A,'Shipment Setup'!$Q:$Q,0)+SUMIFS('Operations Ledger'!$E:$E,'Operations Ledger'!$A:$A,$A10,'Operations Ledger'!$B:$B,"Clenny",'Operations Ledger'!$F:$F,"Yes"))+((F10-(XLOOKUP($A10,'Shipment Setup'!$A:$A,'Shipment Setup'!$N:$N,0)+SUMIFS('Operations Ledger'!$E:$E,'Operations Ledger'!$A:$A,$A10,'Operations Ledger'!$F:$F,"Yes")))*IF((XLOOKUP($A10,'Shipment Setup'!$A:$A,'Shipment Setup'!$Q:$Q,0)+SUMIFS('Operations Ledger'!$E:$E,'Operations Ledger'!$A:$A,$A10,'Operations Ledger'!$B:$B,"Clenny",'Operations Ledger'!$F:$F,"Yes")+XLOOKUP($A10,'Shipment Setup'!$A:$A,'Shipment Setup'!$R:$R,0)+SUMIFS('Operations Ledger'!$E:$E,'Operations Ledger'!$A:$A,$A10,'Operations Ledger'!$B:$B,"Clanny",'Operations Ledger'!$F:$F,"Yes"))=0,0,(XLOOKUP($A10,'Shipment Setup'!$A:$A,'Shipment Setup'!$Q:$Q,0)+SUMIFS('Operations Ledger'!$E:$E,'Operations Ledger'!$A:$A,$A10,'Operations Ledger'!$B:$B,"Clenny",'Operations Ledger'!$F:$F,"Yes"))/(XLOOKUP($A10,'Shipment Setup'!$A:$A,'Shipment Setup'!$Q:$Q,0)+SUMIFS('Operations Ledger'!$E:$E,'Operations Ledger'!$A:$A,$A10,'Operations Ledger'!$B:$B,"Clenny",'Operations Ledger'!$F:$F,"Yes")+XLOOKUP($A10,'Shipment Setup'!$A:$A,'Shipment Setup'!$R:$R,0)+SUMIFS('Operations Ledger'!$E:$E,'Operations Ledger'!$A:$A,$A10,'Operations Ledger'!$B:$B,"Clanny",'Operations Ledger'!$F:$F,"Yes"))))-SUMIFS('Sales Ledger'!$K:$K,'Sales Ledger'!$A:$A,$A10,'Sales Ledger'!$L:$L,"Clenny"))} | J10: {=IF($A10="","",(XLOOKUP($A10,'Shipment Setup'!$A:$A,'Shipment Setup'!$R:$R,0)+SUMIFS('Operations Ledger'!$E:$E,'Operations Ledger'!$A:$A,$A10,'Operations Ledger'!$B:$B,"Clanny",'Operations Ledger'!$F:$F,"Yes"))+((F10-(XLOOKUP($A10,'Shipment Setup'!$A:$A,'Shipment Setup'!$N:$N,0)+SUMIFS('Operations Ledger'!$E:$E,'Operations Ledger'!$A:$A,$A10,'Operations Ledger'!$F:$F,"Yes")))*IF((XLOOKUP($A10,'Shipment Setup'!$A:$A,'Shipment Setup'!$Q:$Q,0)+SUMIFS('Operations Ledger'!$E:$E,'Operations Ledger'!$A:$A,$A10,'Operations Ledger'!$B:$B,"Clenny",'Operations Ledger'!$F:$F,"Yes")+XLOOKUP($A10,'Shipment Setup'!$A:$A,'Shipment Setup'!$R:$R,0)+SUMIFS('Operations Ledger'!$E:$E,'Operations Ledger'!$A:$A,$A10,'Operations Ledger'!$B:$B,"Clanny",'Operations Ledger'!$F:$F,"Yes"))=0,0,(XLOOKUP($A10,'Shipment Setup'!$A:$A,'Shipment Setup'!$R:$R,0)+SUMIFS('Operations Ledger'!$E:$E,'Operations Ledger'!$A:$A,$A10,'Operations Ledger'!$B:$B,"Clanny",'Operations Ledger'!$F:$F,"Yes"))/(XLOOKUP($A10,'Shipment Setup'!$A:$A,'Shipment Setup'!$Q:$Q,0)+SUMIFS('Operations Ledger'!$E:$E,'Operations Ledger'!$A:$A,$A10,'Operations Ledger'!$B:$B,"Clenny",'Operations Ledger'!$F:$F,"Yes")+XLOOKUP($A10,'Shipment Setup'!$A:$A,'Shipment Setup'!$R:$R,0)+SUMIFS('Operations Ledger'!$E:$E,'Operations Ledger'!$A:$A,$A10,'Operations Ledger'!$B:$B,"Clanny",'Operations Ledger'!$F:$F,"Yes"))))-SUMIFS('Sales Ledger'!$K:$K,'Sales Ledger'!$A:$A,$A10,'Sales Ledger'!$L:$L,"Clanny"))} | K10: {=IF($A10="","",XLOOKUP($A10,'Shipment Setup'!$A:$A,'Shipment Setup'!$S:$S,""))}
A11: =IF('Shipment Setup'!A11="","",'Shipment Setup'!A11) | B11: {=IF($A11="","",XLOOKUP($A11,'Shipment Setup'!$A:$A,'Shipment Setup'!$B:$B,""))} | C11: {=IF($A11="","",XLOOKUP($A11,'Shipment Setup'!$A:$A,'Shipment Setup'!$C:$C,""))} | D11: {=IF($A11="","",XLOOKUP($A11,'Shipment Setup'!$A:$A,'Shipment Setup'!$N:$N,0))} | E11: {=IF($A11="","",XLOOKUP($A11,'Shipment Setup'!$A:$A,'Shipment Setup'!$P:$P,0))} | F11: =IF($A11="","",SUMIFS('Sales Ledger'!$K:$K,'Sales Ledger'!$A:$A,$A11)) | G11: =IF($A11="","",SUMIFS('Sales Ledger'!$I:$I,'Sales Ledger'!$A:$A,$A11)) | H11: {=IF($A11="","",MAX(0,XLOOKUP($A11,'Shipment Setup'!$A:$A,'Shipment Setup'!$L:$L,0)-G11))} | I11: {=IF($A11="","",(XLOOKUP($A11,'Shipment Setup'!$A:$A,'Shipment Setup'!$Q:$Q,0)+SUMIFS('Operations Ledger'!$E:$E,'Operations Ledger'!$A:$A,$A11,'Operations Ledger'!$B:$B,"Clenny",'Operations Ledger'!$F:$F,"Yes"))+((F11-(XLOOKUP($A11,'Shipment Setup'!$A:$A,'Shipment Setup'!$N:$N,0)+SUMIFS('Operations Ledger'!$E:$E,'Operations Ledger'!$A:$A,$A11,'Operations Ledger'!$F:$F,"Yes")))*IF((XLOOKUP($A11,'Shipment Setup'!$A:$A,'Shipment Setup'!$Q:$Q,0)+SUMIFS('Operations Ledger'!$E:$E,'Operations Ledger'!$A:$A,$A11,'Operations Ledger'!$B:$B,"Clenny",'Operations Ledger'!$F:$F,"Yes")+XLOOKUP($A11,'Shipment Setup'!$A:$A,'Shipment Setup'!$R:$R,0)+SUMIFS('Operations Ledger'!$E:$E,'Operations Ledger'!$A:$A,$A11,'Operations Ledger'!$B:$B,"Clanny",'Operations Ledger'!$F:$F,"Yes"))=0,0,(XLOOKUP($A11,'Shipment Setup'!$A:$A,'Shipment Setup'!$Q:$Q,0)+SUMIFS('Operations Ledger'!$E:$E,'Operations Ledger'!$A:$A,$A11,'Operations Ledger'!$B:$B,"Clenny",'Operations Ledger'!$F:$F,"Yes"))/(XLOOKUP($A11,'Shipment Setup'!$A:$A,'Shipment Setup'!$Q:$Q,0)+SUMIFS('Operations Ledger'!$E:$E,'Operations Ledger'!$A:$A,$A11,'Operations Ledger'!$B:$B,"Clenny",'Operations Ledger'!$F:$F,"Yes")+XLOOKUP($A11,'Shipment Setup'!$A:$A,'Shipment Setup'!$R:$R,0)+SUMIFS('Operations Ledger'!$E:$E,'Operations Ledger'!$A:$A,$A11,'Operations Ledger'!$B:$B,"Clanny",'Operations Ledger'!$F:$F,"Yes"))))-SUMIFS('Sales Ledger'!$K:$K,'Sales Ledger'!$A:$A,$A11,'Sales Ledger'!$L:$L,"Clenny"))} | J11: {=IF($A11="","",(XLOOKUP($A11,'Shipment Setup'!$A:$A,'Shipment Setup'!$R:$R,0)+SUMIFS('Operations Ledger'!$E:$E,'Operations Ledger'!$A:$A,$A11,'Operations Ledger'!$B:$B,"Clanny",'Operations Ledger'!$F:$F,"Yes"))+((F11-(XLOOKUP($A11,'Shipment Setup'!$A:$A,'Shipment Setup'!$N:$N,0)+SUMIFS('Operations Ledger'!$E:$E,'Operations Ledger'!$A:$A,$A11,'Operations Ledger'!$F:$F,"Yes")))*IF((XLOOKUP($A11,'Shipment Setup'!$A:$A,'Shipment Setup'!$Q:$Q,0)+SUMIFS('Operations Ledger'!$E:$E,'Operations Ledger'!$A:$A,$A11,'Operations Ledger'!$B:$B,"Clenny",'Operations Ledger'!$F:$F,"Yes")+XLOOKUP($A11,'Shipment Setup'!$A:$A,'Shipment Setup'!$R:$R,0)+SUMIFS('Operations Ledger'!$E:$E,'Operations Ledger'!$A:$A,$A11,'Operations Ledger'!$B:$B,"Clanny",'Operations Ledger'!$F:$F,"Yes"))=0,0,(XLOOKUP($A11,'Shipment Setup'!$A:$A,'Shipment Setup'!$R:$R,0)+SUMIFS('Operations Ledger'!$E:$E,'Operations Ledger'!$A:$A,$A11,'Operations Ledger'!$B:$B,"Clanny",'Operations Ledger'!$F:$F,"Yes"))/(XLOOKUP($A11,'Shipment Setup'!$A:$A,'Shipment Setup'!$Q:$Q,0)+SUMIFS('Operations Ledger'!$E:$E,'Operations Ledger'!$A:$A,$A11,'Operations Ledger'!$B:$B,"Clenny",'Operations Ledger'!$F:$F,"Yes")+XLOOKUP($A11,'Shipment Setup'!$A:$A,'Shipment Setup'!$R:$R,0)+SUMIFS('Operations Ledger'!$E:$E,'Operations Ledger'!$A:$A,$A11,'Operations Ledger'!$B:$B,"Clanny",'Operations Ledger'!$F:$F,"Yes"))))-SUMIFS('Sales Ledger'!$K:$K,'Sales Ledger'!$A:$A,$A11,'Sales Ledger'!$L:$L,"Clanny"))} | K11: {=IF($A11="","",XLOOKUP($A11,'Shipment Setup'!$A:$A,'Shipment Setup'!$S:$S,""))}
